<?xml version="1.0"?>
<robot xmlns:xacro="http://wiki.ros.org/xacro">
  <!--
    Base UR robot series xacro macro.

    NOTE this is NOT a URDF. It cannot directly be loaded by consumers
    expecting a flattened '.urdf' file. See the top-level '.xacro' for that
    (but note that .xacro must still be processed by the xacro command).

    This file models the base kinematic chain of a UR robot, which then gets
    parameterised by various configuration files to convert it into a UR3(e),
    UR5(e), UR10(e) or UR16e.

    NOTE the default kinematic parameters (i.e., link lengths, frame locations,
    offsets, etc) do not correspond to any particular robot. They are defaults
    only. There WILL be non-zero offsets between the Forward Kinematics results
    in TF (i.e., robot_state_publisher) and the values reported by the Teach
    Pendant.

    For accurate (and robot-specific) transforms, the 'kinematics_parameters_file'
    parameter MUST point to a .yaml file containing the appropriate values for
    the targeted robot.

    If using the UniversalRobots/Universal_Robots_ROS_Driver, follow the steps
    described in the readme of that repository to extract the kinematic
    calibration from the controller and generate the required .yaml file.

    Main author of the migration to yaml configs Ludovic Delval.

    Contributors to previous versions (in no particular order)

     - Denis Stogl
     - Lovro Ivanov
     - Felix Messmer
     - Kelsey Hawkins
     - Wim Meeussen
     - Shaun Edwards
     - Nadia Hammoudeh Garcia
     - Dave Hershberger
     - G. vd. Hoorn
     - Philip Long
     - Dave Coleman
     - Miguel Prada
     - Mathias Luedtke
     - Marcel Schnirring
     - Felix von Drigalski
     - Felix Exner
     - Jimmy Da Silva
     - Ajit Krisshna N L
     - Muhammad Asif Rana
  -->

  <xacro:include filename="$(find ur_description)/urdf/inc/ur_transmissions.xacro" />
  <xacro:include filename="$(find ur_description)/urdf/inc/ur_common.xacro" />

  <xacro:macro name="ur_robot" params="
    name
    tf_prefix
    parent
    *origin
    joint_limits_parameters_file
    kinematics_parameters_file
    physical_parameters_file
    visual_parameters_file
    generate_ros2_control_tag:=true
    transmission_hw_interface:=hardware_interface/PositionJointInterface
    safety_limits:=false
    safety_pos_margin:=0.15
    safety_k_position:=20
    use_fake_hardware:=false
    fake_sensor_commands:=false
    sim_gazebo:=false
    sim_ignition:=false
    headless_mode:=false
    initial_positions:=${dict(shoulder_pan_joint=0.0,shoulder_lift_joint=-1.57,elbow_joint=0.0,wrist_1_joint=-1.57,wrist_2_joint=0.0,wrist_3_joint=0.0)}
    use_tool_communication:=false
    tool_voltage:=0
    tool_parity:=0
    tool_baud_rate:=115200
    tool_stop_bits:=1
    tool_rx_idle_chars:=1.5
    tool_tx_idle_chars:=3.5
    tool_device_name:=/tmp/ttyUR
    tool_tcp_port:=54321
    robot_ip:=0.0.0.0
    script_filename:=to_be_filled_by_ur_robot_driver
    output_recipe_filename:=to_be_filled_by_ur_robot_driver
    input_recipe_filename:=to_be_filled_by_ur_robot_driver
    reverse_port:=50001
    script_sender_port:=50002
    reverse_ip:=0.0.0.0
    script_command_port:=50004
    trajectory_port:=50003
    non_blocking_read:=true
    keep_alive_count:=2"

    >

    <!-- Load configuration data from the provided .yaml files -->
    <xacro:read_model_data
      joint_limits_parameters_file="${joint_limits_parameters_file}"
      kinematics_parameters_file="${kinematics_parameters_file}"
      physical_parameters_file="${physical_parameters_file}"
      visual_parameters_file="${visual_parameters_file}"
      force_abs_paths="${sim_gazebo or sim_ignition}"/>


    <xacro:if value="${generate_ros2_control_tag}">
      <!-- ros2 control include -->
      <xacro:include filename="$(find ur_description)/urdf/ur.ros2_control.xacro" />
      <!-- ros2 control instance -->
      <xacro:ur_ros2_control
        name="${name}"
        use_fake_hardware="${use_fake_hardware}"
        initial_positions="${initial_positions}"
        fake_sensor_commands="${fake_sensor_commands}"
        headless_mode="${headless_mode}"
        sim_gazebo="${sim_gazebo}"
        sim_ignition="${sim_ignition}"
        script_filename="${script_filename}"
        output_recipe_filename="${output_recipe_filename}"
        input_recipe_filename="${input_recipe_filename}"
        tf_prefix="${tf_prefix}"
        hash_kinematics="${kinematics_hash}"
        robot_ip="${robot_ip}"
        use_tool_communication="${use_tool_communication}"
        tool_voltage="${tool_voltage}"
        tool_parity="${tool_parity}"
        tool_baud_rate="${tool_baud_rate}"
        tool_stop_bits="${tool_stop_bits}"
        tool_rx_idle_chars="${tool_rx_idle_chars}"
        tool_tx_idle_chars="${tool_tx_idle_chars}"
        tool_device_name="${tool_device_name}"
        tool_tcp_port="${tool_tcp_port}"
        reverse_port="${reverse_port}"
        script_sender_port="${script_sender_port}"
        reverse_ip="${reverse_ip}"
        script_command_port="${script_command_port}"
        trajectory_port="${trajectory_port}"
        non_blocking_read="${non_blocking_read}"
        keep_alive_count="${keep_alive_count}"
        />
    </xacro:if>

    <!-- Add URDF transmission elements (for ros_control) -->
    <!--<xacro:ur_arm_transmission prefix="${prefix}" hw_interface="${transmission_hw_interface}" />-->
    <!-- Placeholder for ros2_control transmission which don't yet exist -->

    <!-- links -  main serial chain -->
    <link name="${tf_prefix}base_link"/>
    <link name="${tf_prefix}base_link_inertia">
      <visual>
        <origin xyz="0 0 0" rpy="0 0 ${pi}"/>
        <geometry>
          <xacro:get_mesh name="base" type="visual"/>
        </geometry>
      </visual>
      <collision>
        <origin xyz="0 0 0" rpy="0 0 ${pi}"/>
        <geometry>
          <xacro:get_mesh name="base" type="collision"/>
        </geometry>
      </collision>
      <xacro:cylinder_inertial radius="${base_inertia_radius}" length="${base_inertia_length}" mass="${base_mass}">
        <origin xyz="0 0 0" rpy="0 0 0" />
      </xacro:cylinder_inertial>
    </link>
    <link name="${tf_prefix}shoulder_link">
      <visual>
        <origin xyz="0 0 0" rpy="0 0 ${pi}"/>
        <geometry>
          <xacro:get_mesh name="shoulder" type="visual"/>
        </geometry>
      </visual>
      <collision>
        <origin xyz="0 0 0" rpy="0 0 ${pi}"/>
        <geometry>
          <xacro:get_mesh name="shoulder" type="collision"/>
        </geometry>
      </collision>
      <xacro:cylinder_inertial radius="${shoulder_inertia_radius}" length="${shoulder_inertia_length}" mass="${shoulder_mass}">
        <origin xyz="0 0 0" rpy="0 0 0" />
      </xacro:cylinder_inertial>
    </link>
    <link name="${tf_prefix}upper_arm_link">
      <visual>
        <origin xyz="0 0 ${shoulder_offset}" rpy="${pi/2} 0 ${-pi/2}"/>
        <geometry>
          <xacro:get_mesh name="upper_arm" type="visual"/>
        </geometry>
      </visual>
      <collision>
        <origin xyz="0 0 ${shoulder_offset}" rpy="${pi/2} 0 ${-pi/2}"/>
        <geometry>
          <xacro:get_mesh name="upper_arm" type="collision"/>
        </geometry>
      </collision>
      <xacro:cylinder_inertial radius="${upperarm_inertia_radius}" length="${upperarm_inertia_length}" mass="${upper_arm_mass}">
        <origin xyz="${-0.5 * upperarm_inertia_length} 0.0 ${upper_arm_inertia_offset}" rpy="0 ${pi/2} 0" />
      </xacro:cylinder_inertial>
    </link>
    <link name="${tf_prefix}forearm_link">
      <visual>
        <origin xyz="0 0 ${elbow_offset}" rpy="${pi/2} 0 ${-pi/2}"/>
        <geometry>
          <xacro:get_mesh name="forearm" type="visual"/>
        </geometry>
      </visual>
      <collision>
        <origin xyz="0 0 ${elbow_offset}" rpy="${pi/2} 0 ${-pi/2}"/>
        <geometry>
          <xacro:get_mesh name="forearm" type="collision"/>
        </geometry>
      </collision>
      <xacro:cylinder_inertial radius="${forearm_inertia_radius}" length="${forearm_inertia_length}"  mass="${forearm_mass}">
        <origin xyz="${-0.5 * forearm_inertia_length} 0.0 ${elbow_offset}" rpy="0 ${pi/2} 0" />
      </xacro:cylinder_inertial>
    </link>
    <link name="${tf_prefix}wrist_1_link">
	  <xacro:get_visual_params name="wrist_1" type="visual_offset"/>
      <visual>
      	<origin xyz="0 0 ${visual_params}" rpy="${pi/2} 0 0"/>
        <geometry>
          <xacro:get_mesh name="wrist_1" type="visual"/>
        </geometry>
      </visual>
      <collision>
        <origin xyz="0 0 ${visual_params}" rpy="${pi/2} 0 0"/>
        <geometry>
          <xacro:get_mesh name="wrist_1" type="collision"/>
        </geometry>
      </collision>
      <xacro:cylinder_inertial radius="${wrist_1_inertia_radius}" length="${wrist_1_inertia_length}"  mass="${wrist_1_mass}">
        <origin xyz="0 0 0" rpy="0 0 0" />
      </xacro:cylinder_inertial>
    </link>
    <link name="${tf_prefix}wrist_2_link">
	  <xacro:get_visual_params name="wrist_2" type="visual_offset"/>
      <visual>
        <origin xyz="0 0 ${visual_params}" rpy="0 0 0"/>
        <geometry>
          <xacro:get_mesh name="wrist_2" type="visual"/>
        </geometry>
      </visual>
      <collision>
        <origin xyz="0 0 ${visual_params}" rpy="0 0 0"/>
        <geometry>
          <xacro:get_mesh name="wrist_2" type="collision"/>
        </geometry>
      </collision>
      <xacro:cylinder_inertial radius="${wrist_2_inertia_radius}" length="${wrist_2_inertia_length}"  mass="${wrist_2_mass}">
        <origin xyz="0 0 0" rpy="0 0 0" />
      </xacro:cylinder_inertial>
    </link>
    
    
    <link name="${tf_prefix}wrist_3_link">
	  <xacro:get_visual_params name="wrist_3" type="visual_offset"/>
      <visual>
        <origin xyz="0 0 ${visual_params}" rpy="${pi/2} 0 0"/>
        <geometry>
          <xacro:get_mesh name="wrist_3" type="visual"/>
        </geometry>
      </visual>
      <collision>
        <origin xyz="0 0 ${visual_params}" rpy="${pi/2} 0 0"/>
        <geometry>
          <xacro:get_mesh name="wrist_3" type="collision"/>
        </geometry>
      </collision>
      <xacro:cylinder_inertial radius="${wrist_3_inertia_radius}" length="${wrist_3_inertia_length}"  mass="${wrist_3_mass}">
        <origin xyz="0.0 0.0 ${-0.5 * wrist_3_inertia_length}" rpy="0 0 0" />
      </xacro:cylinder_inertial>
    </link>

    <!-- zivid camera defined as a link-->
    <link name="${tf_prefix}zivid_camera">
      <visual>
        <origin xyz="0.071 0 -0.035" rpy="0 ${-8.5/180} 0" />
        <geometry>
          <box size="0.226 0.089 0.165" />
        </geometry>
        <material name='black' >
          <color rgba="0.8 0.8 0.8 0.6" />
        </material>  
      </visual>
      <collision>
        <origin xyz="0.071 0 -0.035" rpy="0 ${-8.5/180} 0"  />
        <geometry>
          <box size="0.236 0.099 0.175"  />
        </geometry>
      </collision>
			<inertial>
    		<mass value="2"/>
   			<inertia ixx="0.0056" ixy="0.0" ixz="0.0" iyy="0.0056" iyz="0.0" izz="0.0056"/>
  		</inertial>
    </link>

    <!-- base EE for insertion-->
    <link name="${tf_prefix}EE_insertion_base">
      <visual>
        <origin xyz="0 0 -0.08425" rpy="0 0 0" />
        <geometry>
          <cylinder radius="0.01" length="0.1685"/>
        </geometry>
        <material name='green' >
          <color rgba="0 1 0 0.5" />
        </material>  
      </visual>
      <collision>
        <origin xyz="0 0 -0.0842" rpy="0 0 0" />
        <geometry>
          <cylinder radius="0.015" length="0.1685"/>
        </geometry>
      </collision>
    </link>


    <!-- base_joint fixes base_link to the environment -->
    <joint name="${tf_prefix}base_joint" type="fixed">
      <xacro:insert_block name="origin" />
      <parent link="${parent}" />
      <child link="${tf_prefix}base_link" />
    </joint>

    <!-- joints - main serial chain -->
    <joint name="${tf_prefix}base_link-base_link_inertia" type="fixed">
      <parent link="${tf_prefix}base_link" />
      <child link="${tf_prefix}base_link_inertia" />
      <!-- 'base_link' is REP-103 aligned (so X+ forward), while the internal
           frames of the robot/controller have X+ pointing backwards.
           Use the joint between 'base_link' and 'base_link_inertia' (a dummy
           link/frame) to introduce the necessary rotation over Z (of pi rad).
      -->
      <origin xyz="0 0 0" rpy="0 0 ${pi}" />
    </joint>
    <joint name="${tf_prefix}shoulder_pan_joint" type="revolute">
      <parent link="${tf_prefix}base_link_inertia" />
      <child link="${tf_prefix}shoulder_link" />
      <origin xyz="${shoulder_x} ${shoulder_y} ${shoulder_z}" rpy="${shoulder_roll} ${shoulder_pitch} ${shoulder_yaw}" />
      <axis xyz="0 0 1" />
      <limit lower="${shoulder_pan_lower_limit}" upper="${shoulder_pan_upper_limit}"
        effort="${shoulder_pan_effort_limit}" velocity="${shoulder_pan_velocity_limit}"/>
      <xacro:if value="${safety_limits}">
         <safety_controller soft_lower_limit="${shoulder_pan_lower_limit + safety_pos_margin}" soft_upper_limit="${shoulder_pan_upper_limit - safety_pos_margin}" k_position="${safety_k_position}" k_velocity="0.0"/>
      </xacro:if>
      <dynamics damping="0" friction="0"/>
    </joint>
    <joint name="${tf_prefix}shoulder_lift_joint" type="revolute">
      <parent link="${tf_prefix}shoulder_link" />
      <child link="${tf_prefix}upper_arm_link" />
      <origin xyz="${upper_arm_x} ${upper_arm_y} ${upper_arm_z}" rpy="${upper_arm_roll} ${upper_arm_pitch} ${upper_arm_yaw}" />
      <axis xyz="0 0 1" />
      <limit lower="${shoulder_lift_lower_limit}" upper="${shoulder_lift_upper_limit}"
        effort="${shoulder_lift_effort_limit}" velocity="${shoulder_lift_velocity_limit}"/>
      <xacro:if value="${safety_limits}">
         <safety_controller soft_lower_limit="${shoulder_lift_lower_limit + safety_pos_margin}" soft_upper_limit="${shoulder_lift_upper_limit - safety_pos_margin}" k_position="${safety_k_position}" k_velocity="0.0"/>
      </xacro:if>
      <dynamics damping="0" friction="0"/>
    </joint>
    <joint name="${tf_prefix}elbow_joint" type="revolute">
      <parent link="${tf_prefix}upper_arm_link" />
      <child link="${tf_prefix}forearm_link" />
      <origin xyz="${forearm_x} ${forearm_y} ${forearm_z}" rpy="${forearm_roll} ${forearm_pitch} ${forearm_yaw}" />
      <axis xyz="0 0 1" />
      <limit lower="${elbow_joint_lower_limit}" upper="${elbow_joint_upper_limit}"
        effort="${elbow_joint_effort_limit}" velocity="${elbow_joint_velocity_limit}"/>
      <xacro:if value="${safety_limits}">
         <safety_controller soft_lower_limit="${elbow_joint_lower_limit + safety_pos_margin}" soft_upper_limit="${elbow_joint_upper_limit - safety_pos_margin}" k_position="${safety_k_position}" k_velocity="0.0"/>
      </xacro:if>
      <dynamics damping="0" friction="0"/>
    </joint>
    <joint name="${tf_prefix}wrist_1_joint" type="revolute">
      <parent link="${tf_prefix}forearm_link" />
      <child link="${tf_prefix}wrist_1_link" />
      <origin xyz="${wrist_1_x} ${wrist_1_y} ${wrist_1_z}" rpy="${wrist_1_roll} ${wrist_1_pitch} ${wrist_1_yaw}" />
      <axis xyz="0 0 1" />
      <limit lower="${wrist_1_lower_limit}" upper="${wrist_1_upper_limit}"
        effort="${wrist_1_effort_limit}" velocity="${wrist_1_velocity_limit}"/>
      <xacro:if value="${safety_limits}">
         <safety_controller soft_lower_limit="${wrist_1_lower_limit + safety_pos_margin}" soft_upper_limit="${wrist_1_upper_limit - safety_pos_margin}" k_position="${safety_k_position}" k_velocity="0.0"/>
      </xacro:if>
      <dynamics damping="0" friction="0"/>
    </joint>
    <joint name="${tf_prefix}wrist_2_joint" type="revolute">
      <parent link="${tf_prefix}wrist_1_link" />
      <child link="${tf_prefix}wrist_2_link" />
      <origin xyz="${wrist_2_x} ${wrist_2_y} ${wrist_2_z}" rpy="${wrist_2_roll} ${wrist_2_pitch} ${wrist_2_yaw}" />
      <axis xyz="0 0 1" />
      <limit lower="${wrist_2_lower_limit}" upper="${wrist_2_upper_limit}"
             effort="${wrist_2_effort_limit}" velocity="${wrist_2_velocity_limit}"/>
      <xacro:if value="${safety_limits}">
         <safety_controller soft_lower_limit="${wrist_2_lower_limit + safety_pos_margin}" soft_upper_limit="${wrist_2_upper_limit - safety_pos_margin}" k_position="${safety_k_position}" k_velocity="0.0"/>
      </xacro:if>
      <dynamics damping="0" friction="0"/>
    </joint>
    <joint name="${tf_prefix}wrist_3_joint" type="revolute">
      <parent link="${tf_prefix}wrist_2_link" />
      <child link="${tf_prefix}wrist_3_link" />
      <origin xyz="${wrist_3_x} ${wrist_3_y} ${wrist_3_z}" rpy="${wrist_3_roll} ${wrist_3_pitch} ${wrist_3_yaw}" />
      <axis xyz="0 0 1" />
      <limit lower="${wrist_3_lower_limit}" upper="${wrist_3_upper_limit}"
             effort="${wrist_3_effort_limit}" velocity="${wrist_3_velocity_limit}"/>
      <xacro:if value="${safety_limits}">
         <safety_controller soft_lower_limit="${wrist_3_lower_limit + safety_pos_margin}" soft_upper_limit="${wrist_3_upper_limit - safety_pos_margin}" k_position="${safety_k_position}" k_velocity="0.0"/>
      </xacro:if>
      <dynamics damping="0" friction="0"/>
    </joint>

    <link name="${tf_prefix}ft_frame"/>
    <joint name="${tf_prefix}wrist_3_link-ft_frame" type="fixed">
      <parent link="${tf_prefix}wrist_3_link"/>
      <child link="${tf_prefix}ft_frame"/>
      <origin xyz="0 0 0" rpy="${pi} 0 0"/>
    </joint>

    <!-- ROS-Industrial 'base' frame - base_link to UR 'Base' Coordinates transform -->
    <link name="${tf_prefix}base"/>
    <joint name="${tf_prefix}base_link-base_fixed_joint" type="fixed">
      <!-- Note the rotation over Z of pi radians - as base_link is REP-103
           aligned (i.e., has X+ forward, Y+ left and Z+ up), this is needed
           to correctly align 'base' with the 'Base' coordinate system of
           the UR controller.
      -->
      <origin xyz="0 0 0" rpy="0 0 ${pi}"/>
      <parent link="${tf_prefix}base_link"/>
      <child link="${tf_prefix}base"/>
    </joint>

    <!-- ROS-Industrial 'flange' frame - attachment point for EEF models -->
    <link name="${tf_prefix}flange" />
    <joint name="${tf_prefix}wrist_3-flange" type="fixed">
      <parent link="${tf_prefix}wrist_3_link" />
      <child link="${tf_prefix}flange" />
      <!-- <origin xyz="0 0 0" rpy="0 ${-pi/2.0} ${-pi/2.0}" />  original configuration, why is the flange rotated??-->
      <origin xyz="0 0 0" rpy="0 0 0" />
    </joint>

    <!-- Original tool0 frame-->
    <!-- ROS-Industrial 'tool0' frame - all-zeros tool frame -->
    
    <!-- <link name="${tf_prefix}tool0"/>
    <joint name="${tf_prefix}flange-tool0" type="fixed"> -->
      <!-- default toolframe - X+ left, Y+ up, Z+ front -->
      <!-- <origin xyz="0 0 0" rpy="${pi/2.0} 0 ${pi/2.0}"/>
      <parent link="${tf_prefix}flange"/>
      <child link="${tf_prefix}tool0"/>
    </joint>
    -->

    <!-- tool0 frame modified to fit the EE_insertion tool-->
    <link name="${tf_prefix}tool0"/>
    <joint name="${tf_prefix}EE_insertion_tool-tool0" type="fixed">
      <origin xyz="0 0 0" rpy="0 0 0"/>
      <parent link="${tf_prefix}EE_insertion_base"/>
      <child link="${tf_prefix}tool0"/>
    </joint>

    <!-- joint between the flange and the zivid camera-->
    <joint name="${tf_prefix}flange-zivid_camera" type="fixed">
      <!-- <origin xyz=" 0.071 0.104 0.059 " rpy="0 ${12.5/180} ${pi}"/> -->
      <!-- <origin xyz=" 0.06576 0.09706 ${0.1685-0.10786}" rpy="-0.0177 -0.1471 3.1098"/> --> <!-- tf matrix from zivid eye-in-hand calibration -->
      <origin xyz=" 0.06576 0.09706 ${0.1685-0.10786}" rpy="0 ${(8.5*pi)/180} ${pi}"/>
      <parent link="${tf_prefix}flange"/>
      <child link="${tf_prefix}zivid_camera"/>
    </joint>

    <!-- joint between the flange and the EE insertion tool-->
    <joint name="${tf_prefix}flange-EE_insertion_tool" type="fixed">
      <origin xyz=" 0.0 0.0 0.1685 " rpy="0 0 0"/>
      <parent link="${tf_prefix}flange"/>
      <child link="${tf_prefix}EE_insertion_base"/>
    </joint>

    <link name="${tf_prefix}zivid_camera_frame"/>
    <joint name="${tf_prefix}zivid_camera-zivid_camera_frame" type="fixed">
      <origin xyz=" 0 0 0 " rpy="0 0 0"/>
      <parent link="${tf_prefix}zivid_camera"/>
      <child link="${tf_prefix}zivid_camera_frame"/>
    </joint>

  </xacro:macro>
</robot>
